Workbook
Name BAB: Características!$K$31
Name CHA_MOD: Características!$E$22
Name Class: Características!$A$3
Name Class1: Características!$A$3
Name Class2: Características!$A$7
Name Class3: Características!$A$9
Name CON_MOD: Características!$E$16
Name DES_MAX: Equipamiento!$H$10
Name DES_MÁX.: Equipamiento!$H$10
Name DEX_MOD: Características!$E$14
Name HD: Características!$M$16
Name HDLVL: Características!$K$3
Name HDT: Características!$Q$16
Name INT_MOD: Características!$E$18
Name LVL: Características!$I$3
Name LVL_2: Características!$E$7
Name LVL_3: Características!$E$9
Name LVLADJ: Características!$M$3
Name SIZE: Características!$A$5
Name SIZE_MOD: Características!$W$14
Name SPB: Características!$X$17
Name SPBT: Características!$Y$17
Name SpellClass: Equipamiento!$U$51
Name STR_MOD: Características!$E$12
Name Type: Características!$E$3
Name WIS_MOD: Características!$E$20

Sheet Características
A2: NOMBRE DE PERSONAJE | K2: JUGADOR
T3: -
A4: Clase 1ria | E4: TIPO | I4: Nivel 1rio | K4: TIPO Nivel | M4: Ajuste lvl | O4: RAZA | S4: ALINEAMIENTO | W4: DEIDAD
A6: TAMAÑO | E6: EDAD | G6: GÉNERO | I6: ALTURA | K6: PESO | O6: OJOS | S6: PELO | W6: PIEL
AB8: Cavar | AE8: → | AH8: CASILLAS | AM8: CASILLAS CORRIENDO
AB9: Trepar | AE9: → | AH9: CASILLAS | AM9: CASILLAS CORRIENDO
AB10: Nadar | AE10: → | AH10: CASILLAS | AM10: CASILLAS CORRIENDO
A11: NOMBRE CARACT. | C11: PUNTOS CARCT. | E11: MODIFIC. CARACT. | G11: PUNTOS TEMPORALES | I11: MODIFIC. TEMPORAL | M11: TOTAL | O11: HERIDAS | S11: / | T11: PV RESTANTES | Y11: DAÑO NO LETAL | AB11: Vuelo | AE11: → | AH11: CASILLAS | AM11: CASILLAS CORRIENDO
A12: FUE | D12: = | H12: = | K12: PV | S12: / | AB12: Terrestre | AE12: → | AH12: CASILLAS | AM12: CASILLAS CORRIENDO
A14: DES | D14: = | H14: = | K14: CA | N14: = | P14: + | R14: + | T14: + | V14: + | X14: + | Z14: + | AC14: + | AF14: REDUCCIÓN AL DAÑO
O15: BASE | Q15: Bonus Armadura | S15: Bonus escudo | U15: Mod. Destreza | W15: Modificador Tamaño | Y15: Armadura Natural | AA15: Modificador Desvio | AC15: Modificiador Miscelanea
A16: CON | D16: = | H16: = | K16: DG Clase | O16: DG Tipo
U17: Puntos habilidad base | Z17: HABILIDADES
A18: INT | D18: = | H18: = | K18: TOQUE | O18: DESPREVENIDO | U18: Puntos totales | X18: 0
U19: HABILIDAD CLASICA X / BLANK | V19: NOMBRE DE HABILIDAD | AA19: HABILID. CLAVE | AB19: TOTAL | AD19: Modificadores Habilidad | AF19: RANGOS | AH19: Modificadores Miscelanea
A20: SAB | D20: = | H20: = | K20: INICIATIVA | P20: = | R20: + | V20: ABRIR CERRADURAS | AA20: DES | AC20: = | AE20: + | AG20: + | AJ20: +
O21: TOTAL | Q21: DEX MODIFIER | S21: MISC MODIFIER | V21: ARTE ( | X21: Herrería | Z21: ) | AA21: INT | AC21: = | AE21: + | AG21: + | AJ21: +
A22: CAR | D22: = | H22: = | V22: ARTE ( | Z22: ) | AA22: INT | AC22: = | AE22: + | AG22: + | AJ22: +
A23: Total | C23: 0 | D23: = | E23: 0 base | V23: ARTE ( | Z23: ) | AA23: INT | AC23: = | AE23: + | AG23: + | AJ23: +
A24: Tiros de Salvación | E24: TOTAL | G24: SALVACIÓN BASE | I24: MODIFIC. HABILIDAD | K24: MODIFIC. MÁGICO | M24: MODIFIC. MISC. | O24: MODIFIC. TEMPORAL | Q24: MODIFICADOR CONDICIONAL | V24: AVERIGUAR INTENCIONES | AA24: SAB | AC24: = | AE24: + | AG24: + | AJ24: +
A25: FORTALEZA | F25: = | H25: + | J25: + | L25: + | N25: + | P25: + | V25: AVISTAR | AA25: SAB | AC25: = | AE25: + | AG25: + | AJ25: +
I26: Constitución | V26: BUSCAR | AA26: INT | AC26: = | AE26: + | AG26: + | AJ26: +
A27: REFLEJOS | F27: = | H27: + | J27: + | L27: + | N27: + | P27: + | V27: CONCENTRACIÓN | AA27: CON | AC27: = | AE27: + | AG27: + | AJ27: +
I28: Destreza | V28: CONOCIMIENTO DE CONJ. | AA28: INT | AC28: = | AE28: + | AG28: + | AI28: =ROUNDDOWN((AF49/5*2),0)+ROUNDDOWN((AF66/5*2),0) -> 0 | AJ28: +
A29: VOLUNTAD | F29: = | H29: + | J29: + | L29: + | N29: + | P29: + | V29: DESCIFRAR ESCRITURA | AA29: INT | AC29: = | AE29: + | AG29: + | AJ29: +
I30: Sabiduría | V30: DIPLOMACIA | AA30: CAR | AC30: = | AE30: + | AG30: + | AI30: =ROUNDDOWN((AF24/5*2),0)+ROUNDDOWN((AF32/5*2),0)+ROUNDDOWN((AF57/5*2),0) -> 0 | AJ30: +
A31: ATAQUE BASE | M31: RESISTENCIA CONJUROS | V31: DISFRAZARSE | AA31: CAR | AC31: = | AE31: + | AG31: + | AJ31: +
V32: ENGAÑAR | AA32: CAR | AC32: = | AE32: + | AG32: + | AJ32: +
E33: TOTAL | G33: ATAQUE BASE BONUS | K33: MODIFIC. HABILIDAD | M33: MODIFIC TAMAÑO | O33: MODIFIC. MISCELAN. | V33: EQUILIBRIO | AA33: DES* | AC33: = | AE33: + | AG33: + | AI33: =ROUNDDOWN((AF47/5*2),0) -> 0 | AJ33: + | AK33: =MIN(IF(Equipamiento!B54>Equipamiento!B56,Tablas!H293,-Equipamiento!A12-Equipamiento!H15),IF(Equipamiento!B54>Equipamiento!B57,Tablas!H294,Equipamiento!A12-Equipamiento!H15),-Equipamiento!A12-Equipamiento!H15) -> 0
A34: FUERZA | F34: = | J34: + | L34: + | N34: + | V34: ESCAPISMO | AA34: DES* | AC34: = | AE34: + | AG34: + | AJ34: + | AK34: =MIN(IF(Equipamiento!B54>Equipamiento!B56,Tablas!H293,-Equipamiento!A12-Equipamiento!H15),IF(Equipamiento!B54>Equipamiento!B57,Tablas!H294,Equipamiento!A12-Equipamiento!H15),-Equipamiento!A12-Equipamiento!H15) -> 0
K35: Fuerza | V35: ESCONDERSE | AA35: DES* | AC35: = | AE35: + | AG35: + | AJ35: + | AK35: =MIN(IF(Equipamiento!B54>Equipamiento!B56,Tablas!H293,-Equipamiento!A12-Equipamiento!H15),IF(Equipamiento!B54>Equipamiento!B57,Tablas!H294,Equipamiento!A12-Equipamiento!H15),-Equipamiento!A12-Equipamiento!H15)+VLOOKUP(SIZE,Tablas!$A$59:$I$67,9,FALSE()) -> #N/A
A36: DESTREZA | F36: = | J36: + | L36: + | N36: + | V36: ESCUCHAR | AA36: SAB | AC36: = | AE36: + | AG36: + | AJ36: +
K37: Destreza | V37: FALSIFICAR | AA37: INT | AC37: = | AE37: + | AG37: + | AJ37: +
A38: PRESA | F38: = | J38: + | L38: + | N38: + | V38: INTERPRETAR (_________) | AA38: CAR | AC38: = | AE38: + | AG38: + | AJ38: +
K39: Fuerza | V39: INTERPRETAR (_________) | AA39: CAR | AC39: = | AE39: + | AG39: + | AJ39: +
V40: INTERPRETAR (_________) | AA40: CAR | AC40: = | AE40: + | AG40: + | AJ40: +
V41: INTIMIDAR | AA41: CAR | AC41: = | AE41: + | AG41: + | AJ41: +
A42: ARMA | G42: ATAQUE | J42: DAÑO | O42: CRITICO | V42: INUTILIZAR MECANISMO | AA42: INT | AC42: = | AE42: + | AG42: + | AJ42: +
V43: JUEGO DE MANOS | AA43: DES | AC43: = | AE43: + | AG43: + | AI43: =ROUNDDOWN((AF32/5*2),0) -> 0 | AJ43: + | AK43: =MIN(IF(Equipamiento!B54>Equipamiento!B56,Tablas!H293,-Equipamiento!A12-Equipamiento!H15),IF(Equipamiento!B54>Equipamiento!B57,Tablas!H294,Equipamiento!A12-Equipamiento!H15),-Equipamiento!A12-Equipamiento!H15) -> 0
V44: MONTAR (_____________) | AA44: DES | AC44: = | AE44: + | AG44: + | AI44: =ROUNDDOWN((AF64/5*2),0) -> 0 | AJ44: +
...

Sheet Equipamiento
A2: Campaña: | O2: DOTES | R2: NIVEL | S2: Aptitudes de Clase Principal | V2: Aptitudes de Clase Secundaria | Y2: Aptitudes de Clase Terciaria | AB2: Aptitudes de Clase De Prestigio | AE2: Aptitudes de Clase Épica
A3: Puntos de experiencia | G3: Exp. Para level up | H3: Nivel Personaje | J3: Nº DE DOTES | R3: 1.º
R5: 2.º
J6: CARACT. ADICIONALES
A7: EQUIPO | R7: 3.º
A9: Armadura/ Obj. Protector | D9: Tipo | E9: Bonif. A la CA | H9: DES MÁX. | R9: 4.º
H10: 6
A11: Penalizador | B11: Fallo Conj. | D11: Velocidad | E11: Peso | G11: Propiedades Especiales | R11: 5.º
R13: 6.º
A14: Escudo/Obj. Protector | D14: Peso | E14: Bonif. A la CA | H14: Penalizador
R15: 7.º
A16: Fallo Conj. | C16: Propiedades Especiales
R17: 8.º
A19: Obj. Protector | D19: Peso | E19: Bonif. A la CA | R19: 9.º
A21: Propiedades Especiales | R21: 10.º
R23: 11.º
A24: Obj. Protector | D24: Peso | E24: Bonif. A la CA
R25: 12.º
A26: Propiedades Especiales | O26: Aptitudes Especiales
R27: 13.º
A29: Otras Posesiones | R29: 14.º
A30: Objeto | B30: Nº | C30: Peso | D30: Objeto | E30: Nº | F30: Peso | G30: Objeto | I30: Nº | J30: Peso | K30: Total 1 | L30: Total 2 | M30: Total 3
G31: Mochila | R31: 15.º | AH31: =MAX(IF(Equipamiento!B54>Equipamiento!B56,Tablas!H293,-Equipamiento!A12-Equipamiento!H15),IF(Equipamiento!B54>Equipamiento!B57,Tablas!H294,Equipamiento!A12-Equipamiento!H15),-Equipamiento!A12-Equipamiento!H15) -> 0
R33: 16.º
R35: 17.º
R37: 18.º
R39: 19.º
R41: 20.º
S46: Salvación Conjuros
U47: MOD. CD | V47: MOD. CARACT.
S49: FALLO CONJ. ARCANO | V49: %
S51: Clase lanzadora de conjuros | U51: -
A54: Peso Total Transportado | O54: Idiomas | S54: Conj. Conocidos | T54: CD Salvación | U54: NIVEL CONJURO | V54: Conjuros diarios | W54: Conjuros adicional
U55: 0 | W55: 0
A56: Carga ligera | D56: Levantar sobre la cabeza (Igual carga máx) | U56: 1.º
A57: Carga media | D57: Levantar del suelo (2x carga máx) | U57: 2.º
A58: Carga pesada | D58: Empujar o arrastrar (5x carga máx) | U58: 3.º
U59: 4.º
A60: DINERO | U60: 5.º
A61: PC | K61: 1 lb por cada 50 monedas | U61: 6.º
...

Sheet Conjuros
A3: CONJUROS | C3: Escuelas de Magia
A4: Nivel de conjuros 0 | C4: Abjuración | D4: Adivinación | E4: Conjuración | F4: Encantamiento | G4: Evocación | H4: Ilusión | I4: Nigromancia | J4: Transmutación
A15: Nivel de conjuros 1 | C15: Abjuración | D15: Adivinación | E15: Conjuración | F15: Encantamiento | G15: Evocación | H15: Ilusión | I15: Nigromancia | J15: Transmutación
A26: Nivel de conjuros 2 | C26: Abjuración | D26: Adivinación | E26: Conjuración | F26: Encantamiento | G26: Evocación | H26: Ilusión | I26: Nigromancia | J26: Transmutación
A37: Nivel de conjuros 3 | C37: Abjuración | D37: Adivinación | E37: Conjuración | F37: Encantamiento | G37: Evocación | H37: Ilusión | I37: Nigromancia | J37: Transmutación
A48: Nivel de conjuros 4 | C48: Abjuración | D48: Adivinación | E48: Conjuración | F48: Encantamiento | G48: Evocación | H48: Ilusión | I48: Nigromancia | J48: Transmutación
A59: Nivel de conjuros 5 | C59: Abjuración | D59: Adivinación | E59: Conjuración | F59: Encantamiento | G59: Evocación | H59: Ilusión | I59: Nigromancia | J59: Transmutación
A70: Nivel de conjuros 6 | C70: Abjuración | D70: Adivinación | E70: Conjuración | F70: Encantamiento | G70: Evocación | H70: Ilusión | I70: Nigromancia | J70: Transmutación
A81: Nivel de conjuros 7 | C81: Abjuración | D81: Adivinación | E81: Conjuración | F81: Encantamiento | G81: Evocación | H81: Ilusión | I81: Nigromancia | J81: Transmutación
A92: Nivel de conjuros 8 | C92: Abjuración | D92: Adivinación | E92: Conjuración | F92: Encantamiento | G92: Evocación | H92: Ilusión | I92: Nigromancia | J92: Transmutación
A103: Nivel de conjuros 9 | C103: Abjuración | D103: Adivinación | E103: Conjuración | F103: Encantamiento | G103: Evocación | H103: Ilusión | I103: Nigromancia | J103: Transmutación
A114: Nivel de conjuros 10 | C114: Abjuración | D114: Adivinación | E114: Conjuración | F114: Encantamiento | G114: Evocación | H114: Ilusión | I114: Nigromancia | J114: Transmutación
A125: Nivel de conjuros 12 | C125: Abjuración | D125: Adivinación | E125: Conjuración | F125: Encantamiento | G125: Evocación | H125: Ilusión | I125: Nigromancia | J125: Transmutación
... A192: Nivel de conjuros 20 | C192: Abjuración | D192: Adivinación | E192: Conjuración | F192: Encantamiento | G192: Evocación | H192: Ilusión | I192: Nigromancia | J192: Transmutación

Sheet Tablas
A1: TIPODE DG | B1: Barbaro | C1: Bardo | D1: Clérigo | E1: Druida | F1: Explorador | G1: Guerrero | H1: Hechicero | I1: Mago | J1: Monje | K1: Paladín | L1: Pícaro | M1: -
A2: Salvación de Fortaleza | B2: =INT(2+LVL/2) -> 2 | C2: =INT(0+LVL/3) -> 0 | D2: =INT(2+LVL/2) -> 2 | E2: =INT(2+LVL/2) -> 2 | F2: =INT(2+LVL/2) -> 2 | G2: =INT(2+LVL/2) -> 2 | H2: =INT(0+LVL/3) -> 0 | I2: =INT(0+LVL/3) -> 0 | J2: =INT(2+LVL/2) -> 2 | K2: =INT(2+LVL/2) -> 2 | L2: =INT(0+LVL/3) -> 0
A3: Salvación de Reflejos | B3: =INT(0+LVL/3) -> 0 | C3: =INT(2+LVL/2) -> 2 | D3: =INT(0+LVL/3) -> 0 | E3: =INT(0+LVL/3) -> 0 | F3: =INT(2+LVL/2) -> 2 | G3: =INT(0+LVL/3) -> 0 | H3: =INT(0+LVL/3) -> 0 | I3: =INT(0+LVL/3) -> 0 | J3: =INT(2+LVL/2) -> 2 | K3: =INT(0+LVL/3) -> 0 | L3: =INT(2+LVL/2) -> 2
A4: Salvación de Voluntad | B4: =INT(0+LVL/3) -> 0 | C4: =INT(2+LVL/2) -> 2 | D4: =INT(2+LVL/2) -> 2 | E4: =INT(2+LVL/2) -> 2 | F4: =INT(0+LVL/3) -> 0 | G4: =INT(0+LVL/3) -> 0 | H4: =INT(2+LVL/2) -> 2 | I4: =INT(2+LVL/2) -> 2 | J4: =INT(2+LVL/2) -> 2 | K4: =INT(0+LVL/3) -> 0 | L4: =INT(0+LVL/3) -> 0
A5: Puntos Habilidad Base | B5: 4 | C5: 6 | D5: 2 | E5: 4 | F5: 6 | G5: 2 | H5: 2 | I5: 2 | J5: 4 | K5: 2 | L5: 8
A6: Dado de golpe | B6: 12 | C6: 6 | D6: 8 | E6: 8 | F6: 8 | G6: 10 | H6: 4 | I6: 4 | J6: 8 | K6: 10 | L6: 6
A7: Ataque Base | B7: =INT(LVL*1) -> 0 | C7: =INT(LVL*0.75) -> 0 | D7: =INT(LVL*0.75) -> 0 | E7: =INT(LVL*0.75) -> 0 | F7: =INT(LVL*1) -> 0 | G7: =INT(LVL*1) -> 0 | H7: =INT(LVL*0.5) -> 0 | I7: =INT(LVL*0.5) -> 0 | J7: =INT(LVL*0.75) -> 0 | K7: =INT(LVL*1) -> 0 | L7: =INT(LVL*0.75) -> 0
B8: BUENO | C8: REGULAR | D8: REGULAR | E8: REGULAR | F8: BUENO | G8: BUENO | H8: MALO | I8: MALO | J8: REGULAR | K8: BUENO | L8: REGULAR
A10: TIPODE DG | B10: Salvación de Fortaleza | C10: Salvación de Reflejos | D10: Salvación de Voluntad | E10: Puntos Hab. Base | F10: Dado de golpe | G10: Ataque Base
A11: Barbaro | B11: =INT(2+LVL/2) -> 2 | C11: =INT(0+LVL/3) -> 0 | D11: =INT(0+LVL/3) -> 0 | E11: 4 | F11: 12 | G11: =INT(LVL*1) -> 0
A12: Bardo | B12: =INT(0+LVL/3) -> 0 | C12: =INT(2+LVL/2) -> 2 | D12: =INT(2+LVL/2) -> 2 | E12: 6 | F12: 6 | G12: =INT(LVL*0.75) -> 0
A13: Clérigo | B13: =INT(2+LVL/2) -> 2 | C13: =INT(0+LVL/3) -> 0 | D13: =INT(2+LVL/2) -> 2 | E13: 2 | F13: 8 | G13: =INT(LVL*0.75) -> 0
A14: Druida | B14: =INT(2+LVL/2) -> 2 | C14: =INT(0+LVL/3) -> 0 | D14: =INT(2+LVL/2) -> 2 | E14: 4 | F14: 8 | G14: =INT(LVL*0.75) -> 0
A15: Explorador | B15: =INT(2+LVL/2) -> 2 | C15: =INT(2+LVL/2) -> 2 | D15: =INT(0+LVL/3) -> 0 | E15: 6 | F15: 8 | G15: =INT(LVL*1) -> 0
A16: Guerrero | B16: =INT(2+LVL/2) -> 2 | C16: =INT(0+LVL/3) -> 0 | D16: =INT(0+LVL/3) -> 0 | E16: 2 | F16: 10 | G16: =INT(LVL*1) -> 0
A17: Hechicero | B17: =INT(0+LVL/3) -> 0 | C17: =INT(0+LVL/3) -> 0 | D17: =INT(2+LVL/2) -> 2 | E17: 2 | F17: 4 | G17: =INT(LVL*0.5) -> 0
A18: Mago | B18: =INT(0+LVL/3) -> 0 | C18: =INT(0+LVL/3) -> 0 | D18: =INT(2+LVL/2) -> 2 | E18: 2 | F18: 4 | G18: =INT(LVL*0.5) -> 0
A19: Monje | B19: =INT(2+LVL/2) -> 2 | C19: =INT(2+LVL/2) -> 2 | D19: =INT(2+LVL/2) -> 2 | E19: 4 | F19: 8 | G19: =INT(LVL*0.75) -> 0
A20: Paladín | B20: =INT(2+LVL/2) -> 2 | C20: =INT(0+LVL/3) -> 0 | D20: =INT(0+LVL/3) -> 0 | E20: 2 | F20: 10 | G20: =INT(LVL*1) -> 0
A21: Pícaro | B21: =INT(0+LVL/3) -> 0 | C21: =INT(2+LVL/2) -> 2 | D21: =INT(0+LVL/3) -> 0 | E21: 8 | F21: 6 | G21: =INT(LVL*0.75) -> 0
A22: -
A23: Adepto | B23: =INT(0+LVL/3) -> 0 | C23: =INT(0+LVL/3) -> 0 | D23: =INT(2+LVL/2) -> 2 | E23: 2 | F23: 6 | G23: =INT(LVL*0.5) -> 0
A24: Aristócrata | B24: =INT(0+LVL/3) -> 0 | C24: =INT(0+LVL/3) -> 0 | D24: =INT(2+LVL/2) -> 2 | E24: 4 | F24: 8 | G24: =INT(LVL*0.75) -> 0
A25: Combatiente | B25: =INT(2+LVL/2) -> 2 | C25: =INT(0+LVL/3) -> 0 | D25: =INT(0+LVL/3) -> 0 | E25: 2 | F25: 10 | G25: =INT(LVL*1) -> 0
A26: Experto | B26: =INT(0+LVL/3) -> 0 | C26: =INT(0+LVL/3) -> 0 | D26: =INT(2+LVL/2) -> 2 | E26: 6 | F26: 6 | G26: =INT(LVL*0.75) -> 0
A27: Plebeyo | B27: =INT(0+LVL/3) -> 0 | C27: =INT(0+LVL/3) -> 0 | D27: =INT(0+LVL/3) -> 0 | E27: 2 | F27: 4 | G27: =INT(LVL*0.5) -> 0
M28: TS VARIABLES
A29: TIPODE DG | B29: Aberración | C29: Ajeno | D29: Animal | E29: Bestia mágica | F29: Cieno | G29: Constructo | H29: Dragón | I29: Elemental (Aire, Fuego) | J29: Elemental (Tierra, Agua) | K29: Fata | L29: Gigante | M29: Humanoide | N29: Humanoide monst. | O29: Muerto viviente | P29: Planta | Q29: Sabandija | R29: -
A30: Salvación de Fortaleza | B30: =INT(0+HDLVL/3) -> 0 | C30: =INT(2+HDLVL/2) -> 2 | D30: =INT(2+HDLVL/2) -> 2 | E30: =INT(2+HDLVL/2) -> 2 | F30: =INT(0+HDLVL/3) -> 0 | G30: =INT(0+HDLVL/3) -> 0 | H30: =INT(2+HDLVL/2) -> 2 | I30: =INT(0+HDLVL/3) -> 0 | J30: =INT(2+HDLVL/2) -> 2 | K30: =INT(0+HDLVL/3) -> 0 | L30: =INT(2+HDLVL/2) -> 2 | M30: =INT(0+HDLVL/3) -> 0 | N30: =INT(0+HDLVL/3) -> 0 | O30: =INT(0+HDLVL/3) -> 0 | P30: =INT(2+HDLVL/2) -> 2 | Q30: =INT(2+HDLVL/2) -> 2
A31: Salvación de Reflejos | B31: =INT(0+HDLVL/3) -> 0 | C31: =INT(2+HDLVL/2) -> 2 | D31: =INT(2+HDLVL/2) -> 2 | E31: =INT(2+HDLVL/2) -> 2 | F31: =INT(0+HDLVL/3) -> 0 | G31: =INT(0+HDLVL/3) -> 0 | H31: =INT(2+HDLVL/2) -> 2 | I31: =INT(2+HDLVL/2) -> 2 | J31: =INT(0+HDLVL/3) -> 0 | K31: =INT(2+HDLVL/2) -> 2 | L31: =INT(0+HDLVL/3) -> 0 | M31: =INT(0+HDLVL/3) -> 0 | N31: =INT(2+HDLVL/2) -> 2 | O31: =INT(0+HDLVL/3) -> 0 | P31: =INT(0+HDLVL/3) -> 0 | Q31: =INT(0+HDLVL/3) -> 0
A32: Salvación de Voluntad | B32: =INT(2+HDLVL/2) -> 2 | C32: =INT(2+HDLVL/2) -> 2 | D32: =INT(0+HDLVL/3) -> 0 | E32: =INT(0+HDLVL/3) -> 0 | F32: =INT(0+HDLVL/3) -> 0 | G32: =INT(0+HDLVL/3) -> 0 | H32: =INT(2+HDLVL/2) -> 2 | I32: =INT(0+HDLVL/3) -> 0 | J32: =INT(0+HDLVL/3) -> 0 | K32: =INT(2+HDLVL/2) -> 2 | L32: =INT(0+HDLVL/3) -> 0 | M32: =INT(0+HDLVL/3) -> 0 | N32: =INT(2+HDLVL/2) -> 2 | O32: =INT(2+HDLVL/2) -> 2 | P32: =INT(0+HDLVL/3) -> 0 | Q32: =INT(0+HDLVL/3) -> 0
A33: Puntos Habilidad Base | B33: 2 | C33: 8 | D33: 2 | E33: 2 | F33: 2 | G33: 2 | H33: 6 | I33: 2 | J33: 2 | K33: 6 | L33: 2 | M33: 2 | N33: 2 | O33: 4 | P33: 2 | Q33: 2
A34: Dado de Golpe | B34: 8 | C34: 8 | D34: 8 | E34: 10 | F34: 10 | G34: 10 | H34: 12 | I34: 8 | J34: 8 | K34: 6 | L34: 8 | M34: 8 | N34: 8 | O34: 12 | P34: 8 | Q34: 8
A35: Ataque Base | B35: =INT(HDLVL*0.75) -> 0 | C35: =INT(HDLVL*1) -> 0 | D35: =INT(HDLVL*0.75) -> 0 | E35: =INT(HDLVL*1) -> 0 | F35: =INT(HDLVL*0.75) -> 0 | G35: =INT(HDLVL*0.75) -> 0 | H35: =INT(HDLVL*1) -> 0 | I35: =INT(HDLVL*0.75) -> 0 | J35: =INT(HDLVL*0.75) -> 0 | K35: =INT(HDLVL*0.5) -> 0 | L35: =INT(HDLVL*0.75) -> 0 | M35: =INT(HDLVL*0.75) -> 0 | N35: =INT(HDLVL*1) -> 0 | O35: =INT(HDLVL*0.5) -> 0 | P35: =INT(HDLVL*0.75) -> 0 | Q35: =INT(HDLVL*0.75) -> 0
B36: REGULAR | C36: BUENO | D36: REGULAR | E36: BUENO | F36: REGULAR | G36: REGULAR | H36: BUENO | I36: REGULAR | J36: REGULAR | K36: MALO | L36: REGULAR | M36: REGULAR | N36: BUENO | O36: MALO | P36: REGULAR | Q36: REGULAR
A38: TIPODE DG | B38: Salvación de Fortaleza | C38: Salvación de Reflejos | D38: Salvación de Voluntad | E38: Puntos Hab. Base | F38: Dado de Golpe | G38: Ataque Base
A39: Aberración | B39: =INT(0+HDLVL/3) -> 0 | C39: =INT(0+HDLVL/3) -> 0 | D39: =INT(2+HDLVL/2) -> 2 | E39: 2 | F39: 8 | G39: =INT(HDLVL*0.75) -> 0
A40: Ajeno | B40: =INT(2+HDLVL/2) -> 2 | C40: =INT(2+HDLVL/2) -> 2 | D40: =INT(2+HDLVL/2) -> 2 | E40: 8 | F40: 8 | G40: =INT(HDLVL*1) -> 0
A41: Animal | B41: =INT(2+HDLVL/2) -> 2 | C41: =INT(2+HDLVL/2) -> 2 | D41: =INT(0+HDLVL/3) -> 0 | E41: 2 | F41: 8 | G41: =INT(HDLVL*0.75) -> 0
A42: Bestia mágica | B42: =INT(2+HDLVL/2) -> 2 | C42: =INT(2+HDLVL/2) -> 2 | D42: =INT(0+HDLVL/3) -> 0 | E42: 2 | F42: 10 | G42: =INT(HDLVL*1) -> 0
...

Sheet Equipo mundano
A1: Contenedores
A3: Objeto | B3: Peso | C3: Capacidad | D3: Precio | E3: Beneficio | F3: Específico
A4: Barril | B4: 30 | C4: 120 | D4: 2po
A5: Bolsa (para el cinto) | B5: 0.5 | C5: 6 | D5: 1po
A6: Cofre | B6: 25 | C6: 100 | D6: 2po
A7: No Mochila | B7: 0 | C7: 0 | D7: 0pc
A8: Mochila | B8: 2 | C8: 50 | D8: 2po | E8: Posible atar Petate, Cuerda y otros.
A9: Mochila Gran calidad | B9: 3 | C9: 75 | D9: 100po | E9: Posible atar Petate, Cuerda, Tienda de Campaña y +1 Fue a llevar equipo
A10: Mochila Militar | B10: 4 | C10: 100 | D10: 500po | E10: Posible desenfundar 4 armas como acción gratuita y +2 Fue a llevar equipo
A11: Odre | B11: 4 | C11: 8 | D11: 1po | F11: 4 usos/1lb uso
A12: Saco | B12: 0.5 | C12: 50 | D12: 1pp
A13: Bolsa para componentes de conjuro | B13: 2 | C13: 12 | D13: 5po

Sheet Notas
A1: Notas:
